Workbook

Sheet Updated
A1: Source | B1: https://docs.google.com/spreadsheets/d/1noiIQSfT7Pdn22VWdLyflMqLTOMU1xkUpMeeUPi905U/edit?usp=sharing | H1: 30 day visits | M1: 90 day visits
A2: Original From Content Calendar | B2: Publication Date | C2: News URL | D2: Contain Images in Between | E2: Long(L) or Short(S) | F2: Word Count | G2: SRA | H2: Users | I2: Sessions | J2: Pageviews | K2: Session Eng. Time | L2: Bounce Rate | M2: Users | N2: Sessions | O2: Pageviews | P2: Session Eng. Time | Q2: Bounce Rate
A3: Intermittent fasting shows promise in improving gut health, weight management | B3: 45440 | C3: news.asu.edu/20240528-health-and-medicine-intermittent-fasting-shows-promise-improving-gut-health-weight | D3: Yes | E3: S | F3: 993 | H3: 5599 | I3: 6084 | J3: 6844 | K3: 0.00027777778 | L3: 0.714 | M3: 5763 | N3: 6322 | O3: 7112 | P3: 0.00028935185 | Q3: 0.7009
A4: ASU research finds link between removal of uterus, brain function | B4: 45440 | C4: news.asu.edu/20240528-health-and-medicine-asu-research-finds-link-between-removal-uterus-brain-function | D4: Yes | E4: L | F4: 1483 | H4: 5147 | I4: 5790 | J4: 6233 | K4: 0.00053240741 | L4: 0.6812 | M4: 6608 | N4: 7439 | O4: 7999 | P4: 0.00055555556 | Q4: 0.647
A5: New global study shows freshwater is disappearing at alarming rates | B5: 45863 | C5: news.asu.edu/20250725-environment-and-sustainability-new-global-study-shows-freshwater-disappearing-alarming | D5: Yes | E5: L | F5: 1115 | H5: 3582 | I5: 4010 | J5: 4380 | K5: 0.00049768519 | L5: 0.4529 | M5: 7207 | N5: 7842 | O5: 8473 | P5: 0.00032407407 | Q5: 0.6361
A6: ASU retains No. 1 in US, top 10 globally in UN Sustainable Development Goals ranking | B6: 45454 | C6: news.asu.edu/20240611-university-news-asu-retains-no-1-us-top-10-globally-impact-ranking-un-sustainable-goals | D6: No | E6: S | F6: 796 | H6: 2905 | I6: 3195 | J6: 3585 | K6: 0.00032407407 | L6: 0.3981 | M6: 3983 | N6: 4547 | O6: 5095 | P6: 0.00034722222 | Q6: 0.3668
A7: ASU-led Southwest Sustainability Innovation Engine funds 8 promising tech startups | B7: 45728 | C7: news.asu.edu/20250312-science-and-technology-asuled-nsf-futures-engine-in-the-southwest-funds-8-promising-startups | D7: Yes | E7: S | F7: 1319 | H7: 1571 | I7: 1893 | J7: 2097 | K7: 0.00032407407 | L7: 0.4675 | M7: 1755 | N7: 2193 | O7: 2443 | P7: 0.00032407407 | Q7: 0.4505
A8: ASU launches SPORTx, a new initiative to unite sports and entrepreneurship | B8: 45777 | C8: news.asu.edu/20250430-business-and-entrepreneurship-asu-launches-sportx-new-initiative-unite-sports-entrepreneurship | D8: No | E8: S | F8: 661 | H8: 1331 | I8: 1632 | J8: 1865 | K8: 0.00027777778 | L8: 0.5576 | M8: 1662 | N8: 2018 | O8: 2292 | P8: 0.00028935185 | Q8: 0.5149
B9: 45897 | C9: https://news.asu.edu/20250828-health-and-medicine-what-you-need-know-about-dust-storms-and-valley-fever | D9: Yes | E9: L | F9: 1144 | H9: 1378 | I9: 1573 | J9: 1742 | K9: 0.00094907407 | L9: 0.3999 | M9: 1550 | N9: 1824 | O9: 2006 | P9: 0.00087962963 | Q9: 0.4189
B10: 45910 | C10: https://news.asu.edu/20250910-science-and-technology-new-cancer-test-can-warn-patients-10-years-treatment-needed | D10: Yes | E10: S | F10: 902 | H10: 1274 | I10: 1546 | J10: 1616 | K10: 0.00050925926 | L10: 0.3365
A11: ASU and GoDaddy launch Student Athlete Venture Studio | B11: 45742 | C11: news.asu.edu/20250325-business-and-entrepreneurship-asu-and-godaddy-launch-studentathlete-venture-studio | D11: No | E11: S | F11: 543 | H11: 1203 | I11: 1417 | J11: 1600 | K11: 0.00019675926 | L11: 0.6422 | M11: 1382 | N11: 1672 | O11: 1876 | P11: 0.00020833333 | Q11: 0.6298
A12: Is your gut microbiome a calorie 'super harvester'? | B12: 45819 | C12: news.asu.edu/20250611-health-and-medicine-your-gut-microbiome-calorie-super-harvester | D12: Yes | E12: S | F12: 941 | H12: 1273 | I12: 1422 | J12: 1529 | K12: 0.00059027778 | L12: 0.41 | M12: 1368 | N12: 1552 | O12: 1667 | P12: 0.00059027778 | Q12: 0.4098
A13: Saving lives from an invisible killer | B13: 45502 | C13: news.asu.edu/20240729-environment-and-sustainability-saving-lives-invisible-killer | D13: Yes | E13: L | F13: 3439 | H13: 864 | I13: 1065 | J13: 1257 | K13: 0.00078703704 | L13: 0.3183 | M13: 1114 | N13: 1388 | O13: 1630 | P13: 0.00068287037 | Q13: 0.2731
A14: Bird flu: Your questions on symptoms, spread and safety answered | B14: 45765 | C14: news.asu.edu/20250418-health-and-medicine-bird-flu-your-questions-symptoms-spread-and-safety-answered | D14: No | E14: L | F14: 2190 | H14: 1042 | I14: 1151 | J14: 1224 | K14: 0.00079861111 | L14: 0.4587 | M14: 1376 | N14: 1523 | O14: 1628 | P14: 0.00078703704 | Q14: 0.4399
A15: New study explores the link between diet, blood sugar and cancer risk across species | B15: 45728 | C15: news.asu.edu/20250312-science-and-technology-new-study-explores-link-between-diet-blood-sugar-and-cancer-risk | D15: Yes | E15: S | F15: 948 | H15: 837 | I15: 948 | J15: 1066 | K15: 0.00045138889 | L15: 0.4694 | M15: 935 | N15: 1059 | O15: 1192 | P15: 0.00047453704 | Q15: 0.4508
B16: 45968 | C16: https://news.asu.edu/20251107-science-and-technology-asu-researchers-discover-dnabased-electronic-storage-system | D16: Yes | E16: S | F16: 618 | H16: 804 | I16: 997 | J16: 1062 | K16: 0.00038194444 | L16: 0.4553
A17: Fast, accurate, low-cost diagnostics: No lab required | ASU News | B17: 45881 | C17: news.asu.edu/20250812-science-and-technology-fast-accurate-lowcost-diagnostics-no-lab-required | D17: Yes | E17: S | F17: 663 | H17: 742 | I17: 889 | J17: 1035 | K17: 0.00047453704 | L17: 0.4094 | M17: 1551 | N17: 1827 | O17: 2074 | P17: 0.00039351852 | Q17: 0.3065
A18: Global Futures Laboratory at ASU joins DOE initiative to empower women in clean energy | B18: 45467 | C18: news.asu.edu/20240624-environment-and-sustainability-global-futures-laboratory-asu-joins-doe-initiative-empower | D18: No | E18: S | F18: 616 | H18: 761 | I18: 890 | J18: 986 | K18: 0.0002662037 | L18: 0.3685 | M18: 825 | N18: 984 | O18: 1091 | P18: 0.0002662037 | Q18: 0.378
A19: NSF-funded, ASU-led sustainability, economic development initiative taps new CEO | B19: 45475 | C19: news.asu.edu/20240702-swsie-appoints-new-ceo | D19: No | E19: L | F19: 1526 | H19: 744 | I19: 881 | J19: 977 | K19: 0.00025462963 | L19: 0.5664 | M19: 901 | N19: 1121 | O19: 1237 | P19: 0.0002662037 | Q19: 0.5174
A20: Fighting the fungus among us | B20: 45761 | C20: news.asu.edu/20250414-health-and-medicine-fighting-fungus-among-us | D20: No | E20: S | F20: 969 | H20: 708 | I20: 845 | J20: 928 | K20: 0.000625 | L20: 0.3515 | M20: 768 | N20: 934 | O20: 1026 | P20: 0.00059027778 | Q20: 0.3437
A21: Study aims to help semiconductor industry be more sustainable | B21: 45856 | C21: news.asu.edu/20250718-science-and-technology-study-aims-help-semiconductor-industry-be-more-sustainable | D21: Yes | E21: S | F21: 562 | H21: 700 | I21: 821 | J21: 921 | K21: 0.00027777778 | L21: 0.3946 | M21: 898 | N21: 1048 | O21: 1163 | P21: 0.0002662037 | Q21: 0.3406
A22: A world full of plastic ... not fantastic | B22: 45616 | C22: news.asu.edu/20241120-environment-and-sustainability-world-full-plastic-not-fantastic | D22: Yes | E22: L | F22: 2743 | H22: 652 | I22: 803 | J22: 891 | K22: 0.00052083333 | L22: 0.528 | M22: 756 | N22: 952 | O22: 1071 | P22: 0.00054398148 | Q22: 0.4853
A23: Adventurer and space visionary embarks on a new journey at ASU | B23: 45687 | C23: news.asu.edu/20250130-environment-and-sustainability-adventurer-and-space-visionary-embarks-new-journey-asu | D23: Yes | E23: L | F23: 1002 | H23: 709 | I23: 820 | J23: 862 | K23: 0.00048611111 | L23: 0.3146 | M23: 740 | N23: 932 | O23: 981 | P23: 0.00043981481 | Q23: 0.3412
A24: 4 ASU researchers named Senior Members of the National Academy of Inventors | B24: 45744 | C24: news.asu.edu/20250328-science-and-technology-four-asu-researchers-named-senior-members-national-academy | D24: Yes | E24: L | F24: 1285 | H24: 655 | I24: 728 | J24: 857 | K24: 0.00049768519 | L24: 0.1484 | M24: 704 | N24: 798 | O24: 945 | P24: 0.00048611111 | Q24: 0.1591
B25: 45951 | C25: https://news.asu.edu/20251021-health-and-medicine-food-medicine-event-cultivates-new-solutions-sustainable-health | D25: Yes | E25: L | F25: 1894 | H25: 668 | I25: 765 | J25: 848 | K25: 0.00048611111 | L25: 0.4601
A26: ASU invention helps people worldwide reach weight goals | B26: 45782 | C26: news.asu.edu/20250505-health-and-medicine-asu-invention-helps-people-worldwide-reach-weight-goals | D26: Yes | E26: S | F26: 744 | H26: 598 | I26: 720 | J26: 820 | K26: 0.00060185185 | L26: 0.2778 | M26: 986 | N26: 1214 | O26: 1375 | P26: 0.00055555556 | Q26: 0.2257
A27: Urban forestry accelerator aims to boost green infrastructure, economic growth in Phoenix | B27: 45509 | C27: news.asu.edu/20240830-environment-and-sustainability-urban-forestry-accelerator-aims-boost-green-infrastructure | D27: No | E27: L | F27: 1130 | H27: 631 | I27: 754 | J27: 813 | K27: 0.00028935185 | L27: 0.5597 | M27: 781 | N27: 968 | O27: 1056 | P27: 0.0003125 | Q27: 0.5145
A28: Improving Alzheimer's prevention and care | B28: 45834 | C28: news.asu.edu/20250626-health-and-medicine-improving-alzheimers-prevention-and-care | D28: Yes | E28: L | F28: 1572 | H28: 593 | I28: 678 | J28: 753 | K28: 0.00087962963 | L28: 0.3319 | M28: 771 | N28: 933 | O28: 1064 | P28: 0.00087962963 | Q28: 0.3033
A29: 8 ways to protect wildlife | B29: 45569 | C29: news.asu.edu/20241004-environment-and-sustainability-8-ways-protect-wildlife | D29: Yes | E29: L | F29: 3201 | H29: 548 | I29: 642 | J29: 753 | K29: 0.00068287037 | L29: 0.3131 | M29: 992 | N29: 1165 | O29: 1359 | P29: 0.00082175926 | Q29: 0.3288
A30: New cancer treatment disrupts tumor growth | B30: 45735 | C30: news.asu.edu/20250319-science-and-technology-new-cancer-treatment-disrupts-tumor-growth | D30: Yes | E30: S | F30: 787 | H30: 575 | I30: 668 | J30: 749 | K30: 0.00049768519 | L30: 0.3518 | M30: 1005 | N30: 1155 | O30: 1291 | P30: 0.00054398148 | Q30: 0.3662
A31: Water-cleaning bacteria can produce health, economic benefits | B31: 45814 | C31: news.asu.edu/20250606-environment-and-sustainability-watercleaning-bacteria-can-produce-health-economic-benefits | D31: Yes | E31: L | F31: 1261 | H31: 462 | I31: 614 | J31: 707 | K31: 0.00047453704 | L31: 0.4235 | M31: 521 | N31: 709 | O31: 818 | P31: 0.00046296296 | Q31: 0.3949
A32: Charles Redman, founder of the School of Sustainability, faces a new adventure: Retirement | B32: 45595 | C32: news.asu.edu/20241030-environment-and-sustainability-charles-redman-founder-school-sustainability-faces-new | D32: Yes | E32: L | F32: 1422 | H32: 562 | I32: 638 | J32: 701 | K32: 0.00082175926 | L32: 0.4577 | M32: 580 | N32: 669 | O32: 737 | P32: 0.00082175926 | Q32: 0.4499
A33: Forest thinning may provide water benefits downstream | B33: 45433 | C33: news.asu.edu/20240521-environment-and-sustainability-forest-thinning-may-provide-water-benefits-downstream | D33: Yes | E33: S | F33: 560 | H33: 519 | I33: 609 | J33: 687 | K33: 0.00039351852 | L33: 0.4795 | M33: 597 | N33: 729 | O33: 819 | P33: 0.00037037037 | Q33: 0.4856
A34: ASU researchers blend biology, fantasy in world-building guidebook | B34: 45805 | C34: news.asu.edu/20250528-science-and-technology-asu-researchers-blend-biology-fantasy-worldbuilding-guidebook | D34: Yes | E34: S | F34: 894 | H34: 472 | I34: 588 | J34: 685 | K34: 0.00038194444 | L34: 0.4286 | M34: 547 | N34: 697 | O34: 803 | P34: 0.00034722222 | Q34: 0.4204
A35: Math and stats grad beats the odds by overcoming serious health issues | B35: 45409 | C35: news.asu.edu/20240427-sun-devil-community-math-and-stats-grad-beats-odds-overcoming-serious-health-issues | D35: Yes | E35: S | F35: 884 | H35: 637 | I35: 827 | J35: 594 | K35: 0.00077546296 | M35: 688 | N35: 893 | O35: 935 | P35: 0.00076388889
A36: ASU helps rural communities tackle local water problems | B36: 45818 | C36: news.asu.edu/20250610-environment-and-sustainability-asu-helps-rural-communities-tackle-local-water-problems | D36: Yes | E36: L | F36: 1646 | H36: 358 | I36: 485 | J36: 590 | K36: 0.00053240741 | L36: 0.3505 | M36: 399 | N36: 565 | O36: 682 | P36: 0.00053240741 | Q36: 0.3345
B37: 45954 | C37: https://news.asu.edu/20251024-science-and-technology-untangling-alzheimers-asu-researchers-tackling-our-understanding | D37: Yes | E37: L | F37: 1583 | H37: 420 | I37: 508 | J37: 577 | K37: 0.00068287037 | L37: 0.3406
A38: Navigating uncharted waters: ASU drives solutions for water resilience | B38: 45538 | C38: news.asu.edu/20240903-environment-and-sustainability-navigating-uncharted-waters-asu-drives-solutions-water | D38: Yes | E38: L | F38: 2539 | H38: 391 | I38: 482 | J38: 571 | K38: 0.00052083333 | L38: 0.3361 | M38: 631 | N38: 777 | O38: 918 | P38: 0.0005787037 | Q38: 0.2638
B39: 45964 | C39: https://news.asu.edu/20251103-science-and-technology-secrets-microbial-motion-how-bacteria-swash-glide-and-shift-gears | D39: Yes | E39: L | F39: 1193 | H39: 382 | I39: 493 | J39: 564 | K39: 0.00040509259 | L39: 0.3915
A40: ASU-led initiative announces first decarbonization projects for US industry | B40: 45573 | C40: news.asu.edu/20241008-science-and-technology-asuled-initiative-announces-first-decarbonization-projects-us | D40: No | E40: L | F40: 1417 | H40: 381 | I40: 470 | J40: 563 | K40: 0.00052083333 | L40: 0.3596 | M40: 521 | N40: 666 | O40: 789 | P40: 0.0005787037 | Q40: 0.364
...

Sheet Original
A1: Source | B1: https://docs.google.com/spreadsheets/d/1noiIQSfT7Pdn22VWdLyflMqLTOMU1xkUpMeeUPi905U/edit?usp=sharing
E2: 30 day visits | J2: 90 day visits
A3: News URL | B3: Contain Images | C3: Long(L) or Short(S) | D3: Image | E3: Users | F3: Sessions | G3: Pageviews | H3: Session Eng. Time | I3: Bounce Rate | J3: Users | K3: Sessions | L3: Pageviews | M3: Session Eng. Time | N3: Bounce Rate
A4: news.asu.edu/20250623-science-and-technology-new-asu-research-hunts-down-drugresistant-microbes | B4: Yes | C4: L | E4: 284 | F4: 353 | G4: 309 | H4: 0.00040509259 | I4: 0.3144 | J4: 284 | K4: 353 | L4: 395 | M4: 0.00040509259 | N4: 0.3144
A5: news.asu.edu/20250626-health-and-medicine-improving-alzheimers-prevention-and-care | B5: Yes | C5: L | E5: 361 | F5: 413 | G5: 461 | H5: 0.00079861111 | I5: 0.2712 | J5: 361 | K5: 413 | L5: 461 | M5: 0.00079861111 | N5: 0.2712
A6: news.asu.edu/20250612-university-news-lu-baird-gifts-support-science-students-and-society-asu | B6: Yes | C6: L | E6: 212 | F6: 244 | G6: 280 | H6: 0.00065972222 | I6: 0.3033 | J6: 212 | K6: 244 | L6: 280 | M6: 0.00065972222 | N6: 0.3033
A7: news.asu.edu/20250611-health-and-medicine-your-gut-microbiome-calorie-super-harvester | B7: Yes | C7: L | E7: 1270 | F7: 1419 | G7: 1526 | H7: 0.00059027778 | I7: 0.4094 | J7: 1273 | K7: 1422 | L7: 1529 | M7: 0.00059027778 | N7: 0.41
A8: news.asu.edu/20250610-environment-and-sustainability-asu-helps-rural-communities-tackle-local-water-problems | B8: Yes | C8: L | E8: 355 | F8: 482 | G8: 587 | H8: 0.00053240741 | I8: 0.3527 | J8: 358 | K8: 485 | L8: 590 | M8: 0.00053240741 | N8: 0.3505
A9: news.asu.edu/20250606-environment-and-sustainability-watercleaning-bacteria-can-produce-health-economic-benefits | B9: Yes | C9: L | E9: 461 | F9: 612 | G9: 705 | H9: 0.00047453704 | I9: 0.4248 | J9: 469 | K9: 623 | L9: 717 | M9: 0.00047453704 | N9: 0.4222
A10: news.asu.edu/20250602-science-and-technology-your-crash-course-quantum-science | B10: Yes | C10: L | E10: 337 | F10: 428 | G10: 487 | H10: 0.00046296296 | I10: 0.4603 | J10: 538 | K10: 668 | L10: 739 | M10: 0.00046296296 | N10: 0.4251
A11: news.asu.edu/20250528-science-and-technology-asu-researchers-blend-biology-fantasy-worldbuilding-guidebook | B11: Yes | C11: S | E11: 469 | F11: 584 | G11: 681 | H11: 0.00039351852 | I11: 0.4264 | J11: 499 | K11: 626 | L11: 725 | M11: 0.00037037037 | N11: 0.4249
A12: news.asu.edu/20250509-health-and-medicine-can-frisky-flies-save-human-lives | B12: Yes | C12: S | E12: 297 | F12: 346 | G12: 401 | H12: 0.00054398148 | I12: 0.4566 | J12: 331 | K12: 389 | L12: 447 | M12: 0.00053240741 | N12: 0.4447
A13: https://news.asu.edu/20250505-health-and-medicine-asu-invention-helps-people-worldwide-reach-weight-goals | B13: Yes | C13: S | E13: 592 | F13: 710 | G13: 805 | H13: 0.00059027778 | I13: 0.2803 | J13: 868 | K13: 1071 | L13: 1218 | M13: 0.00056712963 | N13: 0.2278
A14: https://news.asu.edu/20250501-sun-devil-community-asu-mba-graduates-journey-cancer-research-business-leadership
A15: https://news.asu.edu/20250502-sun-devil-community-sea-turtles-science-policy-how-asu-grad-found-his-path-phd
A16: https://news.asu.edu/20250501-sun-devil-community-mentorship-helped-asu-graduate-find-passion-immunology
A17: https://news.asu.edu/20250430-business-and-entrepreneurship-asu-launches-sportx-new-initiative-unite-sports-entrepreneurship | B17: Yes | C17: S | E17: 1315 | F17: 1609 | G17: 1839 | H17: 0.00027777778 | I17: 0.56 | J17: 1604 | K17: 1995 | L17: 2269 | M17: 0.00028935185 | N17: 0.5163
A18: news.asu.edu/20250430-business-and-entrepreneurship-asu-launches-sportx-new-initiative-unite-sports-entrepreneurship | B18: Yes | C18: S | E18: 1327 | F18: 1628 | G18: 1860 | H18: 0.00027777778 | I18: 0.5584 | J18: 1547 | K18: 1916 | L18: 2178 | M18: 0.00028935185 | N18: 0.5261
A19: news.asu.edu/20250421-environment-and-sustainability-majority-american-religious-leaders-silently-believe-climate-change | B19: Yes | C19: S | E19: 191 | F19: 210 | G19: 229 | H19: 0.0003125 | I19: 0.4524 | J19: 202 | K19: 234 | L19: 255 | M19: 0.00028935185 | N19: 0.4487
A20: news.asu.edu/20250418-health-and-medicine-bird-flu-your-questions-symptoms-spread-and-safety-answered | B20: Yes | C20: L | E20: 1034 | F20: 1143 | G20: 1215 | H20: 0.00079861111 | I20: 0.4611 | J20: 1353 | K20: 1496 | L20: 1601 | M20: 0.00079861111 | N20: 0.4398
A21: news.asu.edu/20250418-environment-and-sustainability-k12-corporate-upskilling-asu-guides-learners-all-ages | B21: Yes | C21: L | E21: 358 | F21: 457 | G21: 499 | H21: 0.00030092593 | I21: 0.4333 | J21: 396 | K21: 507 | L21: 552 | M21: 0.00030092593 | N21: 0.4398
A22: news.asu.edu/20250414-health-and-medicine-fighting-fungus-among-us | B22: Yes | C22: S | E22: 705 | F22: 841 | G22: 924 | H22: 0.000625 | I22: 0.3508 | J22: 767 | K22: 933 | L22: 1025 | M22: 0.00059027778 | N22: 0.3441
A23: news.asu.edu/20250402-environment-and-sustainability-asu-amazon-student-bridges-communities-solar-canoe-project | B23: Yes | C23: L | E23: 365 | F23: 446 | G23: 503 | H23: 0.000625 | I23: 0.3498 | J23: 387 | K23: 477 | L23: 539 | M23: 0.00061342593 | N23: 0.3417
A24: news.asu.edu/20250328-science-and-technology-four-asu-researchers-named-senior-members-national-academy | B24: Yes | C24: L | E24: 641 | F24: 711 | G24: 840 | H24: 0.00049768519 | I24: 0.1491 | J24: 704 | K24: 798 | L24: 945 | M24: 0.00048611111 | N24: 0.1591
A25: news.asu.edu/20250325-business-and-entrepreneurship-asu-and-godaddy-launch-studentathlete-venture-studio | B25: Yes | C25: S | E25: 1154 | F25: 1356 | G25: 1519 | H25: 0.00019675926 | I25: 0.6379 | J25: 1333 | K25: 1607 | L25: 1790 | M25: 0.00019675926 | N25: 0.6297
A26: news.asu.edu/20250325-science-and-technology-asu-students-win-big-homeland-security-design-challenge | B26: Yes | C26: L | E26: 361 | F26: 421 | G26: 482 | H26: 0.00050925926 | I26: 0.3207 | J26: 409 | K26: 480 | L26: 548 | M26: 0.00048611111 | N26: 0.3167
A27: news.asu.edu/20250324-science-and-technology-swarm-science-oral-bacteria-move-waves-spread-and-survive | B27: Yes | C27: S | E27: 299 | F27: 341 | G27: 396 | H27: 0.00039351852 | I27: 0.4516 | J27: 322 | K27: 368 | L27: 426 | M27: 0.00040509259 | N27: 0.4402
A28: news.asu.edu/20250320-health-and-medicine-dynamic-data-duo-advances-health-research | B28: Yes | C28: S | E28: 272 | F28: 321 | G28: 352 | H28: 0.00033564815 | I28: 0.4642 | J28: 314 | K28: 387 | L28: 419 | M28: 0.00030092593 | N28: 0.4419
... A35: news.asu.edu/20250130-environment-and-sustainability-adventurer-and-space-visionary-embarks-new-journey-asu | B35: Yes | C35: S | E35: 709 | F35: 820 | G35: 862 | H35: 0.00048611111 | I35: 0.3146 | J35: 736 | K35: 927 | L35: 974 | M35: 0.00043981481 | N35: 0.342
A36: news.asu.edu/b/20250106-securing-borders-and-supply-chains-and-improving-efficiency-qa-ross-maciejewski
A37: news.asu.edu/b/20241220-rise-humanmachine-teams-qa-jamie-gorman
A38: news.asu.edu/20241202-environment-and-sustainability-pettinger-guide-southwest-sustainability-innovation-engines | B38: Yes | C38: L | E38: 296 | F38: 319 | G38: 350 | H38: 0.00027777778 | I38: 0.5455 | J38: 351 | K38: 398 | L38: 445 | M38: 0.00034722222 | N38: 0.4874
A39: news.asu.edu/20241120-environment-and-sustainability-world-full-plastic-not-fantastic | B39: Yes | C39: L | E39: 650 | F39: 797 | G39: 884 | H39: 0.00052083333 | I39: 0.7754 | J39: 750 | K39: 945 | L39: 1064 | M39: 0.00054398148 | N39: 0.4887
A40: https://news.asu.edu/20241031-science-and-technology-def-con-academy-looks-serve-build-community
A41: news.asu.edu/20241031-environment-and-sustainability-asu-carbon-summit-displays-sustainability-leadership | B41: Yes | C41: L | E41: 559 | F41: 634 | G41: 696 | H41: 0.00082175926 | I41: 0.459 | J41: 580 | K41: 660 | L41: 737 | M41: 0.00082175926 | N41: 0.4499
A42: news.asu.edu/20241028-arts-humanities-and-education-2-killer-halloween-projects-asus-monster-expert | B42: Yes | C42: S | E42: 324 | F42: 397 | G42: 482 | H42: 0.00037037037 | I42: 0.2695 | J42: 341 | K42: 416 | L42: 501 | M42: 0.00038194444 | N42: 0.2716
A43: news.asu.edu/20241028-environment-and-sustainability-10-climate-insights-guide-our-future | B43: Yes | C43: S | E43: 236 | F43: 270 | G43: 302 | H43: 0.00028935185 | I43: 0.3556 | J43: 255 | K43: 300 | L43: 334 | M43: 0.00028935185 | N43: 0.3367
A44: news.asu.edu/20241024-science-and-technology-meet-3-asu-cybersecurity-researchers-advancing-more-secure-future | B44: Yes | C44: S | E44: 348 | F44: 379 | G44: 417 | H44: 0.00028935185 | I44: 0.409 | J44: 409 | K44: 454 | L44: 500 | M44: 0.00027777778 | N44: 0.3722
A45: news.asu.edu/b/20241021-exploring-molecules-motion | B45: Yes | C45: S | E45: 64 | F45: 78 | G45: 92 | H45: 0.00048611111 | I45: 0.2564 | J45: 70 | K45: 89 | L45: 104 | M45: 0.00049768519 | N45: 0.2247
A46: news.asu.edu/b/20241014-stephanie-forrests-unique-integration-computation-biology-and-health | B46: Yes | C46: L | E46: 89 | F46: 119 | G46: 139 | H46: 0.00064814815 | I46: 0.395 | J46: 115 | K46: 155 | L46: 177 | M46: 0.00065972222 | N46: 0.3548
...

Sheet Averages
A1: 30 Days
A2: Avg Users | B2: Avg Sessions | C2: Avg Pageviews | D2: Avg Session Eng. Time | E2: Avg Bounce Rate
A3: =AVERAGE(Updated!H36:H554) -> 246.30952 | B3: =AVERAGE(Updated!I36:I554) -> 292.38095 | C3: =AVERAGE(Updated!J36:J554) -> 331.09524 | D3: =AVERAGE(Updated!K36:K554) -> 0.0004491843 | E3: =AVERAGE(Updated!L36:L554) -> 0.33148784
A5: 90 Days
A6: Avg Users | B6: Avg Sessions | C6: Avg Pageviews | D6: Avg Session Eng. Time | E6: Avg Bounce Rate
A7: =AVERAGE(Updated!M36:M554) -> 319.02817 | B7: =AVERAGE(Updated!N36:N554) -> 385.91549 | C7: =AVERAGE(Updated!O36:O554) -> 433.19718 | D7: =AVERAGE(Updated!P36:P554) -> 0.00045383412 | E7: =AVERAGE(Updated!Q36:Q554) -> 0.34005902

Sheet Comparison
F1: 30 day visits | K1: 90 day visits
A2: Date | B2: Unit | C2: News URL | D2: Contain Images | E2: Long(L) or Short(S) | F2: Users | G2: Sessions | H2: Pageviews | I2: Session Eng. Time | J2: Bounce Rate | K2: Users | L2: Sessions | M2: Pageviews | N2: Session Eng. Time | O2: Bounce Rate
A3: 45440 | B3: KE | C3: news.asu.edu/20240528-health-and-medicine-intermittent-fasting-shows-promise-improving-gut-health-weight | D3: Y | E3: S | F3: 5584 | G3: 6604 | H3: 6824 | I3: 0.00027777778 | J3: 0.7139 | K3: 5755 | L3: 6312 | M3: 7100 | N3: 0.00028935185 | O3: 0.7015
B4: Non-KE | C4: news.asu.edu/20240528-health-and-medicine-asu-research-finds-link-between-removal-uterus-brain-function | D4: Y | E4: L | F4: 5748 | G4: 6479 | H4: 6992 | I4: 0.00052083333 | J4: 0.6751 | K4: 6500 | L4: 7316 | M4: 7865 | N4: 0.00055555556 | O4: 0.6499
A5: 45593 | B5: KE | C5: news.asu.edu/20241028-environment-and-sustainability-10-climate-insights-guide-our-future | D5: Y | E5: S | F5: 236 | G5: 270 | H5: 302 | I5: 0.00028935185 | J5: 0.3556 | K5: 255 | L5: 300 | M5: 334 | N5: 0.00028935185 | O5: 0.3367
B6: Non-KE | C6: news.asu.edu/20241028-arts-humanities-and-education-2-killer-halloween-projects-asus-monster-expert | D6: Y | E6: L
A7: 45518 | B7: KE | C7: news.asu.edu/20240814-environment-and-sustainability-ustda-director-joins-policymakers-business-leaders | D7: Y | E7: S | F7: 359 | G7: 390 | H7: 423 | I7: 0.00020833333 | J7: 0.3513 | K7: 393 | L7: 431 | M7: 468 | N7: 0.00020833333 | O7: 0.3295
B8: Non-KE | C8: news.asu.edu/20240814-environment-and-sustainability-asu-lab-brings-energy | D8: Y | E8: L | F8: 382 | G8: 448 | H8: 519 | I8: 0.00047453704 | J8: 0.2098 | K8: 498 | L8: 592 | M8: 673 | N8: 0.00050925926 | O8: 0.1892
